Workbook
Name Bonus_Month: Assumptions!$C$20
Name Bonus_Percentage: Assumptions!$C$19
Name Company_Name: Assumptions!$C$4
Name Currency_Denominator: Assumptions!$C$10
Name Currency_Disclaimer: Assumptions!$C$6
Name Gross_Margin: 'P&L_Forecast'!$X$23
Name Gross_Profit: 'P&L_Forecast'!$X$22
Name Net_Cash_Flow: Cash_Flow_Forecast!$X$43
Name Net_Margin: 'P&L_Forecast'!$X$36
Name NFL_Confidential_Toggle: Assumptions!$D$71
Name Price_Increase: Assumptions!$C$24
Name Salary_Deductions: Assumptions!$C$18
Name Tax_Rate: Assumptions!$C$12
Name Total_Cash_Receipts: Cash_Flow_Forecast!$X$14
Name Total_COGS: 'P&L_Forecast'!$X$20
Name Total_Direct_Labor: 'P&L_Forecast'!$X$17
Name Total_Sales: 'P&L_Forecast'!$X$14
Name Total_Wages_Benefits: Cash_Flow_Forecast!$X$19
Name Utilities_Minimum_Spend: Assumptions!$C$22

Sheet Assumptions
B1: {=Company_Name} -> Pinnacle Supplier DBA Candy Confection
B2: Model Assumptions
B4: Company Name | C4: Pinnacle Supplier DBA Candy Confection | E4: Scenario Manager
E5: Active | F5: Pessimistic | G5: Base | H5: Optimistic
B6: Currency Disclaimer | C6: ="All figures in "&C10&"s of USD (unless otherwise noted)" -> All figures in 1000s of USD (unless otherwise noted)
D7: NFL Sales | E7: =CHOOSE($J$25,F7,G7,H7) -> TRUE | F7: FALSE | G7: TRUE | H7: TRUE
D9: Hiring | E9: =CHOOSE($J$25,F9,G9,H9) -> TRUE | F9: FALSE | G9: TRUE | H9: TRUE
B10: Currency Denominator | C10: 1000
D11: Capex:
B12: Tax Rate | C12: 0.34 | D12: Kitchen | E12: =CHOOSE($J$25,F12,G12,H12) -> TRUE | F12: FALSE | G12: TRUE | H12: TRUE
D13: Tempering | E13: =CHOOSE($J$25,F13,G13,H13) -> TRUE | F13: FALSE | G13: TRUE | H13: TRUE
B14: Financing | C14: =Capex!U16+Capex!U28+Capex!U40 -> 1185000 | D14: Filler | E14: =CHOOSE($J$25,F14,G14,H14) -> TRUE | F14: FALSE | G14: TRUE | H14: TRUE
B16: Uncollectable Reserve % | C16: =E16 -> 0.03 | E16: =CHOOSE($J$25,F16,G16,H16) -> 0.03 | F16: 0.04 | G16: 0.03 | H16: 0.02
B18: Salary Deductions | C18: =E18 -> 0.01 | E18: =CHOOSE($J$25,F18,G18,H18) -> 0.01 | F18: 0.01 | G18: 0.01 | H18: 0.01
B19: Bonus % | C19: =E19 -> 0.15 | E19: =CHOOSE($J$25,F19,G19,H19) -> 0.15 | F19: 0.1 | G19: 0.15 | H19: 0.18
B20: Bonus Month | C20: 12
B22: Utilities Minimum Spend | C22: =E22 -> 0.75 | E22: =CHOOSE($J$25,F22,G22,H22) -> 0.75 | F22: 0.85 | G22: 0.75 | H22: 0.75
B24: Price Increase | C24: =E24 -> 0.1 | E24: =CHOOSE($J$25,F24,G24,H24) -> 0.1 | F24: 0.05 | G24: 0.1 | H24: 0.15 | J24: Case Assump.
J25: 2
B26: A/R Collection Terms | C26: =E26 -> 60 | E26: =CHOOSE($J$25,F26,G26,H26) -> 60 | F26: 75 | G26: 60 | H26: 30 | J26: Pessimistic
B27: A/P Payment Terms | C27: =E27 -> 37 | E27: =CHOOSE($J$25,F27,G27,H27) -> 37 | F27: 30 | G27: 37 | H27: 45 | J27: Base
B28: Accrued Expense Terms | C28: =E28 -> 30 | E28: =CHOOSE($J$25,F28,G28,H28) -> 30 | F28: 30 | G28: 30 | H28: 30 | J28: Optimistic
B29: Prepaid Expense Terms | C29: =E29 -> 0 | E29: =CHOOSE($J$25,F29,G29,H29) -> 0 | F29: 0 | G29: 0 | H29: 0
B33: Customer_ID | C33: Customer_Name | D33: Status
B34: {=_xlfn.SEQUENCE(COUNTA(_xlfn.ANCHORARRAY($C$34)))} -> 1 | C34: {=_xlfn.UNIQUE(sales_forecast_tbl[Customer Name])} -> Apex Foods Inc. | D34: TRUE
B35: 2 | C35: Beacon Confections | D35: TRUE
B36: 3 | C36: Summit Gourmet Supply | D36: TRUE
B37: 4 | C37: Sterling Fine Foods | D37: TRUE
B38: 5 | C38: Cascade Distributors | D38: TRUE
B39: 6 | C39: Evergreen Specialty Foods | D39: TRUE
B40: 7 | C40: Pinnacle Chocolates LLC | D40: TRUE
B41: 8 | C41: Granite Corporate Catering | D41: TRUE
B42: 9 | C42: Sequoia Imports | D42: TRUE
B43: 10 | C43: Blue Horizon Delicacies | D43: TRUE
B44: 11 | C44: Paramount Foodservice | D44: TRUE
B45: 12 | C45: Crestline Premium Goods | D45: TRUE
B46: 13 | C46: Highland Sweets Distributors | D46: TRUE
... B70: 37 | C70: Titan Hospitality Supplies | D70: TRUE
B71: 38 | C71: NFL Confidential | D71: =E7 -> TRUE
B72: 39 | C72: Sweet Haven Market | D72: TRUE
...

Sheet Cash_Flow_Forecast
B1: {=Company_Name} -> Pinnacle Supplier DBA Candy Confection
B2: Monthly Cash Flow Forecast
B3: =Currency_Disclaimer -> All figures in 1000s of USD (unless otherwise noted)
F5: {=_xlfn.SEQUENCE(1,COUNT(7:7),-COUNTIF($8:$8,"Act"),1)} -> -3 | G5: -2 | H5: -1 | I5: 0 | J5: 1 | K5: 2 | L5: 3 | M5: 4 | N5: 5 | O5: 6 | P5: 7 | Q5: 8 | R5: 9 | S5: 10 | T5: 11 | U5: 12 | V5: 13 | W5: 14
B6: Month # | F6: -3 | G6: -2 | H6: -1 | I6: 0 | J6: =I6+1 -> 1 | K6: =J6+1 -> 2 | L6: =K6+1 -> 3 | M6: =L6+1 -> 4 | N6: =M6+1 -> 5 | O6: =N6+1 -> 6 | P6: =O6+1 -> 7 | Q6: =P6+1 -> 8 | ... V6: =U6+1 -> 13 | X6: =(DAYS360(X7,X8)/30)+1&"-mos" -> 13-mos
B7: Month Ending | F7: 45565 | G7: 45596 | H7: 45626 | I7: 45657 | J7: =EOMONTH($I$7,COLUMNS($I7:J7)-1) -> 45688 | K7: =EOMONTH($I$7,COLUMNS($I7:K7)-1) -> 45716 | L7: =EOMONTH($I$7,COLUMNS($I7:L7)-1) -> 45747 | M7: =EOMONTH($I$7,COLUMNS($I7:M7)-1) -> 45777 | N7: =EOMONTH($I$7,COLUMNS($I7:N7)-1) -> 45808 | O7: =EOMONTH($I$7,COLUMNS($I7:O7)-1) -> 45838 | P7: =EOMONTH($I$7,COLUMNS($I7:P7)-1) -> 45869 | Q7: =EOMONTH($I$7,COLUMNS($I7:Q7)-1) -> 45900 | ... V7: =EOMONTH($I$7,COLUMNS($I7:V7)-1) -> 46053 | X7: 45688
B8: Fcst / Act | F8: Act | G8: Act | H8: Act | I8: Open | J8: Fcst | K8: Fcst | L8: Fcst | M8: Fcst | N8: Fcst | O8: Fcst | P8: Fcst | Q8: Fcst | R8: Fcst | S8: Fcst | T8: Fcst | U8: Fcst | V8: Fcst | X8: 46053
B10: Cash Receipts (Operating):
B12: Trade Receivables | J12: =-SUM('P&L_Forecast'!J47:J50) -> 4788.8719 | K12: =-SUM('P&L_Forecast'!K47:K50) -> 480.53057 | L12: =-SUM('P&L_Forecast'!L47:L50) -> 3686.9755 | M12: =-SUM('P&L_Forecast'!M47:M50) -> 5144.6466 | N12: =-SUM('P&L_Forecast'!N47:N50) -> 669.54313 | O12: =-SUM('P&L_Forecast'!O47:O50) -> 1978.0953 | P12: =-SUM('P&L_Forecast'!P47:P50) -> 1156.3735 | Q12: =-SUM('P&L_Forecast'!Q47:Q50) -> 682.05008 | ... V12: =-SUM('P&L_Forecast'!V47:V50) -> 1807.9513 | X12: =SUM(_xlfn.XLOOKUP($X$7,$I$7:W$7,$I12:W12):_xlfn.XLOOKUP($X$8,$I$7:W$7,$I12:W12)) -> 24173.316
B14: Total Cash Receipts | J14: =SUM(J12:J13) -> 4788.8719 | K14: =SUM(K12:K13) -> 480.53057 | L14: =SUM(L12:L13) -> 3686.9755 | M14: =SUM(M12:M13) -> 5144.6466 | N14: =SUM(N12:N13) -> 669.54313 | O14: =SUM(O12:O13) -> 1978.0953 | P14: =SUM(P12:P13) -> 1156.3735 | Q14: =SUM(Q12:Q13) -> 682.05008 | ... V14: =SUM(V12:V13) -> 1807.9513 | X14: =SUM(_xlfn.XLOOKUP($X$7,$I$7:W$7,$I14:W14):_xlfn.XLOOKUP($X$8,$I$7:W$7,$I14:W14)) -> 24173.316
B16: Cash Disbursements (Operating):
B18: Raw Materials and Production | J18: =SUM('P&L_Forecast'!J61:J62) -> -2871.11 | K18: =SUM('P&L_Forecast'!K61:K62) -> -1969.612 | L18: =SUM('P&L_Forecast'!L61:L62) -> -2748.3117 | M18: =SUM('P&L_Forecast'!M61:M62) -> -357.67534 | N18: =SUM('P&L_Forecast'!N61:N62) -> -1056.7145 | O18: =SUM('P&L_Forecast'!O61:O62) -> -617.74404 | P18: =SUM('P&L_Forecast'!P61:P62) -> -364.35665 | Q18: =SUM('P&L_Forecast'!Q61:Q62) -> -367.8579 | ... V18: =SUM('P&L_Forecast'!V61:V62) -> -1409.0603 | X18: =SUM(_xlfn.XLOOKUP($X$7,$I$7:W$7,$I18:W18):_xlfn.XLOOKUP($X$8,$I$7:W$7,$I18:W18)) -> -14378.793
B19: Wages & Benefits | J19: =(SUM('P&L_Forecast'!J70:J71)+SUM('P&L_Forecast'!J84:J85)+'P&L_Forecast'!J91) -> -671.77611 | K19: =(SUM('P&L_Forecast'!K70:K71)+SUM('P&L_Forecast'!K84:K85)+'P&L_Forecast'!K91) -> -935.52096 | L19: =(SUM('P&L_Forecast'!L70:L71)+SUM('P&L_Forecast'!L84:L85)+'P&L_Forecast'!L91) -> -467.54643 | M19: =(SUM('P&L_Forecast'!M70:M71)+SUM('P&L_Forecast'!M84:M85)+'P&L_Forecast'!M91) -> -434.09036 | N19: =(SUM('P&L_Forecast'!N70:N71)+SUM('P&L_Forecast'!N84:N85)+'P&L_Forecast'!N91) -> -406.89792 | O19: =(SUM('P&L_Forecast'!O70:O71)+SUM('P&L_Forecast'!O84:O85)+'P&L_Forecast'!O91) -> -308.34622 | P19: =(SUM('P&L_Forecast'!P70:P71)+SUM('P&L_Forecast'!P84:P85)+'P&L_Forecast'!P91) -> -308.52345 | Q19: =(SUM('P&L_Forecast'!Q70:Q71)+SUM('P&L_Forecast'!Q84:Q85)+'P&L_Forecast'!Q91) -> -307.74554 | ... V19: =(SUM('P&L_Forecast'!V70:V71)+SUM('P&L_Forecast'!V84:V85)+'P&L_Forecast'!V91) -> -789.09906 | X19: =SUM(_xlfn.XLOOKUP($X$7,$I$7:W$7,$I19:W19):_xlfn.XLOOKUP($X$8,$I$7:W$7,$I19:W19)) -> -6887.6449
B20: Facility Rent | J20: =-'P&L_Forecast'!J106 -> -25 | K20: =-'P&L_Forecast'!K106 -> -25 | L20: =-'P&L_Forecast'!L106 -> -25 | M20: =-'P&L_Forecast'!M106 -> -25 | N20: =-'P&L_Forecast'!N106 -> -25 | O20: =-'P&L_Forecast'!O106 -> -25 | P20: =-'P&L_Forecast'!P106 -> -25 | Q20: =-'P&L_Forecast'!Q106 -> -25 | ... V20: =-'P&L_Forecast'!V106 -> -25 | X20: =SUM(_xlfn.XLOOKUP($X$7,$I$7:W$7,$I20:W20):_xlfn.XLOOKUP($X$8,$I$7:W$7,$I20:W20)) -> -325
B21: Other Operating Expenses | J21: ='P&L_Forecast'!J99 -> -56 | K21: ='P&L_Forecast'!K99 -> -77.378891 | L21: ='P&L_Forecast'!L99 -> -107.26197 | M21: ='P&L_Forecast'!M99 -> -21.118933 | N21: ='P&L_Forecast'!N99 -> -41.241784 | O21: ='P&L_Forecast'!O99 -> -26.249724 | P21: ='P&L_Forecast'!P99 -> -21.250746 | Q21: ='P&L_Forecast'!Q99 -> -21.319821 | ... V21: ='P&L_Forecast'!V99 -> -54.993245 | X21: =SUM(_xlfn.XLOOKUP($X$7,$I$7:W$7,$I21:W21):_xlfn.XLOOKUP($X$8,$I$7:W$7,$I21:W21)) -> -539.25964
B23: Total Operating Cash Disbursements | J23: =SUM(J18:J22) -> -3623.8861 | K23: =SUM(K18:K22) -> -3007.5119 | L23: =SUM(L18:L22) -> -3348.1201 | M23: =SUM(M18:M22) -> -837.88464 | N23: =SUM(N18:N22) -> -1529.8542 | O23: =SUM(O18:O22) -> -977.33998 | P23: =SUM(P18:P22) -> -719.13084 | Q23: =SUM(Q18:Q22) -> -721.92326 | ... V23: =SUM(V18:V22) -> -2278.1526 | X23: =SUM(_xlfn.XLOOKUP($X$7,$I$7:W$7,$I23:W23):_xlfn.XLOOKUP($X$8,$I$7:W$7,$I23:W23)) -> -22130.698
B25: Operating Cash Flow | J25: =J14+J23 -> 1164.9858 | K25: =K14+K23 -> -2526.9813 | L25: =L14+L23 -> 338.85541 | M25: =M14+M23 -> 4306.7619 | N25: =N14+N23 -> -860.31105 | O25: =O14+O23 -> 1000.7554 | P25: =P14+P23 -> 437.24264 | Q25: =Q14+Q23 -> -39.87318 | ... V25: =V14+V23 -> -470.20129 | X25: =SUM(_xlfn.XLOOKUP($X$7,$I$7:W$7,$I25:W25):_xlfn.XLOOKUP($X$8,$I$7:W$7,$I25:W25)) -> 2042.6181
B28: Cash Disbursements (Non-Operating):
B30: Capital Expenditures | J30: =-'P&L_Forecast'!J114 -> 0 | K30: =-'P&L_Forecast'!K114 -> -80 | L30: =-'P&L_Forecast'!L114 -> -145 | M30: =-'P&L_Forecast'!M114 -> -600 | N30: =-'P&L_Forecast'!N114 -> 0 | O30: =-'P&L_Forecast'!O114 -> -360 | P30: =-'P&L_Forecast'!P114 -> 0 | Q30: =-'P&L_Forecast'!Q114 -> 0 | ... V30: =-'P&L_Forecast'!V114 -> 0 | X30: =SUM(_xlfn.XLOOKUP($X$7,$I$7:W$7,$I30:W30):_xlfn.XLOOKUP($X$8,$I$7:W$7,$I30:W30)) -> -1185
B31: Taxes | J31: =-IF(-'P&L_Forecast'!J123>=0,-'P&L_Forecast'!J123,0) -> 0 | K31: =-IF(-'P&L_Forecast'!K123>=0,-'P&L_Forecast'!K123,0) -> 0 | L31: =-IF(-'P&L_Forecast'!L123>=0,-'P&L_Forecast'!L123,0) -> -791.14496 | M31: =-IF(-'P&L_Forecast'!M123>=0,-'P&L_Forecast'!M123,0) -> 0 | N31: =-IF(-'P&L_Forecast'!N123>=0,-'P&L_Forecast'!N123,0) -> 0 | O31: =-IF(-'P&L_Forecast'!O123>=0,-'P&L_Forecast'!O123,0) -> -162.95687 | P31: =-IF(-'P&L_Forecast'!P123>=0,-'P&L_Forecast'!P123,0) -> 0 | Q31: =-IF(-'P&L_Forecast'!Q123>=0,-'P&L_Forecast'!Q123,0) -> 0 | ... V31: =-IF(-'P&L_Forecast'!V123>=0,-'P&L_Forecast'!V123,0) -> 0 | X31: =SUM(_xlfn.XLOOKUP($X$7,$I$7:W$7,$I31:W31):_xlfn.XLOOKUP($X$8,$I$7:W$7,$I31:W31)) -> -1294.0237
B33: Total Non-Operating Cash Disbursements | J33: =SUM(J30:J32) -> 0 | K33: =SUM(K30:K32) -> -80 | L33: =SUM(L30:L32) -> -936.14496 | M33: =SUM(M30:M32) -> -600 | N33: =SUM(N30:N32) -> 0 | O33: =SUM(O30:O32) -> -522.95687 | P33: =SUM(P30:P32) -> 0 | Q33: =SUM(Q30:Q32) -> 0 | ... W33: =SUM(W30:W32) -> 0 | X33: =SUM(_xlfn.XLOOKUP($X$7,$I$7:W$7,$I33:W33):_xlfn.XLOOKUP($X$8,$I$7:W$7,$I33:W33)) -> -2479.0237
B36: Cash Flow (Pre-Financing) | J36: =J25+J33 -> 1164.9858 | K36: =K25+K33 -> -2606.9813 | L36: =L25+L33 -> -597.28955 | M36: =M25+M33 -> 3706.7619 | N36: =N25+N33 -> -860.31105 | O36: =O25+O33 -> 477.7985 | P36: =P25+P33 -> 437.24264 | Q36: =Q25+Q33 -> -39.87318 | ... V36: =V25+V33 -> -470.20129 | X36: =SUM(_xlfn.XLOOKUP($X$7,$I$7:W$7,$I36:W36):_xlfn.XLOOKUP($X$8,$I$7:W$7,$I36:W36)) -> -436.40568
B38: + Equipment Financing | J38: =(Debt_Service!$C$7*(Debt_Service!$C$9=Cash_Flow_Forecast!J$7)) / Currency_Denominator -> 1185 | K38: =(Debt_Service!$C$7*(Debt_Service!$C$9=Cash_Flow_Forecast!K$7)) / Currency_Denominator -> 0 | L38: =(Debt_Service!$C$7*(Debt_Service!$C$9=Cash_Flow_Forecast!L$7)) / Currency_Denominator -> 0 | M38: =(Debt_Service!$C$7*(Debt_Service!$C$9=Cash_Flow_Forecast!M$7)) / Currency_Denominator -> 0 | N38: =(Debt_Service!$C$7*(Debt_Service!$C$9=Cash_Flow_Forecast!N$7)) / Currency_Denominator -> 0 | O38: =(Debt_Service!$C$7*(Debt_Service!$C$9=Cash_Flow_Forecast!O$7)) / Currency_Denominator -> 0 | P38: =(Debt_Service!$C$7*(Debt_Service!$C$9=Cash_Flow_Forecast!P$7)) / Currency_Denominator -> 0 | Q38: =(Debt_Service!$C$7*(Debt_Service!$C$9=Cash_Flow_Forecast!Q$7)) / Currency_Denominator -> 0 | ... V38: =(Debt_Service!$C$7*(Debt_Service!$C$9=Cash_Flow_Forecast!V$7)) / Currency_Denominator -> 0 | X38: =SUM(_xlfn.XLOOKUP($X$7,$I$7:W$7,$I38:W38):_xlfn.XLOOKUP($X$8,$I$7:W$7,$I38:W38)) -> 1185
B39: - Loan Amortization | J39: =_xlfn.XLOOKUP(J$7,Debt_Service!$F$7:$F$42,Debt_Service!$K$7:$K$42) / Currency_Denominator -> 0 | K39: =_xlfn.XLOOKUP(K$7,Debt_Service!$F$7:$F$42,Debt_Service!$K$7:$K$42) / Currency_Denominator -> 0 | L39: =_xlfn.XLOOKUP(L$7,Debt_Service!$F$7:$F$42,Debt_Service!$K$7:$K$42) / Currency_Denominator -> -92.116795 | M39: =_xlfn.XLOOKUP(M$7,Debt_Service!$F$7:$F$42,Debt_Service!$K$7:$K$42) / Currency_Denominator -> 0 | N39: =_xlfn.XLOOKUP(N$7,Debt_Service!$F$7:$F$42,Debt_Service!$K$7:$K$42) / Currency_Denominator -> 0 | O39: =_xlfn.XLOOKUP(O$7,Debt_Service!$F$7:$F$42,Debt_Service!$K$7:$K$42) / Currency_Denominator -> -93.27306 | P39: =_xlfn.XLOOKUP(P$7,Debt_Service!$F$7:$F$42,Debt_Service!$K$7:$K$42) / Currency_Denominator -> 0 | Q39: =_xlfn.XLOOKUP(Q$7,Debt_Service!$F$7:$F$42,Debt_Service!$K$7:$K$42) / Currency_Denominator -> 0 | ... V39: =_xlfn.XLOOKUP(V$7,Debt_Service!$F$7:$F$42,Debt_Service!$K$7:$K$42) / Currency_Denominator -> 0 | X39: =SUM(_xlfn.XLOOKUP($X$7,$I$7:W$7,$I39:W39):_xlfn.XLOOKUP($X$8,$I$7:W$7,$I39:W39)) -> -375.463
B40: - Loan Interest | J40: =_xlfn.XLOOKUP(J$7,Debt_Service!$F$7:$F$42,Debt_Service!$O$7:$O$42) / Currency_Denominator -> 0 | K40: =_xlfn.XLOOKUP(K$7,Debt_Service!$F$7:$F$42,Debt_Service!$O$7:$O$42) / Currency_Denominator -> 0 | L40: =_xlfn.XLOOKUP(L$7,Debt_Service!$F$7:$F$42,Debt_Service!$O$7:$O$42) / Currency_Denominator -> -14.429744 | M40: =_xlfn.XLOOKUP(M$7,Debt_Service!$F$7:$F$42,Debt_Service!$O$7:$O$42) / Currency_Denominator -> 0 | N40: =_xlfn.XLOOKUP(N$7,Debt_Service!$F$7:$F$42,Debt_Service!$O$7:$O$42) / Currency_Denominator -> 0 | O40: =_xlfn.XLOOKUP(O$7,Debt_Service!$F$7:$F$42,Debt_Service!$O$7:$O$42) / Currency_Denominator -> -13.27348 | P40: =_xlfn.XLOOKUP(P$7,Debt_Service!$F$7:$F$42,Debt_Service!$O$7:$O$42) / Currency_Denominator -> 0 | Q40: =_xlfn.XLOOKUP(Q$7,Debt_Service!$F$7:$F$42,Debt_Service!$O$7:$O$42) / Currency_Denominator -> 0 | ... V40: =_xlfn.XLOOKUP(V$7,Debt_Service!$F$7:$F$42,Debt_Service!$O$7:$O$42) / Currency_Denominator -> 0 | X40: =SUM(_xlfn.XLOOKUP($X$7,$I$7:W$7,$I40:W40):_xlfn.XLOOKUP($X$8,$I$7:W$7,$I40:W40)) -> -50.723153
B43: Net Cash Flow | J43: =J36+SUM(J38:J42) -> 2349.9858 | K43: =K36+SUM(K38:K42) -> -2606.9813 | L43: =L36+SUM(L38:L42) -> -703.83609 | M43: =M36+SUM(M38:M42) -> 3706.7619 | N43: =N36+SUM(N38:N42) -> -860.31105 | O43: =O36+SUM(O38:O42) -> 371.25196 | P43: =P36+SUM(P38:P42) -> 437.24264 | Q43: =Q36+SUM(Q38:Q42) -> -39.87318 | ... V43: =V36+SUM(V38:V42) -> -470.20129 | X43: =SUM(_xlfn.XLOOKUP($X$7,$I$7:W$7,$I43:W43):_xlfn.XLOOKUP($X$8,$I$7:W$7,$I43:W43)) -> 322.40817

Sheet P&L_Forecast
B1: {=Company_Name} -> Pinnacle Supplier DBA Candy Confection
B2: Financial Forecast
B3: =Currency_Disclaimer -> All figures in 1000s of USD (unless otherwise noted)
F5: {=_xlfn.SEQUENCE(1,COUNT(7:7),-COUNTIF($8:$8,"Act"),1)} -> -3 | G5: -2 | H5: -1 | I5: 0 | J5: 1 | K5: 2 | L5: 3 | M5: 4 | N5: 5 | O5: 6 | P5: 7 | Q5: 8 | R5: 9 | S5: 10 | T5: 11 | U5: 12 | V5: 13 | W5: 14
B6: Month # | F6: -3 | G6: -2 | H6: -1 | I6: 0 | J6: =I6+1 -> 1 | K6: =J6+1 -> 2 | L6: =K6+1 -> 3 | M6: =L6+1 -> 4 | N6: =M6+1 -> 5 | O6: =N6+1 -> 6 | P6: =O6+1 -> 7 | Q6: =P6+1 -> 8 | ... V6: =U6+1 -> 13 | X6: =(DAYS360(X7,X8)/30)+1&"-mos" -> 13-mos
B7: Month Ending | F7: 45565 | G7: 45596 | H7: 45626 | I7: 45657 | J7: =EOMONTH($I$7,COLUMNS($I7:J7)-1) -> 45688 | K7: =EOMONTH($I$7,COLUMNS($I7:K7)-1) -> 45716 | L7: =EOMONTH($I$7,COLUMNS($I7:L7)-1) -> 45747 | M7: =EOMONTH($I$7,COLUMNS($I7:M7)-1) -> 45777 | N7: =EOMONTH($I$7,COLUMNS($I7:N7)-1) -> 45808 | O7: =EOMONTH($I$7,COLUMNS($I7:O7)-1) -> 45838 | P7: =EOMONTH($I$7,COLUMNS($I7:P7)-1) -> 45869 | Q7: =EOMONTH($I$7,COLUMNS($I7:Q7)-1) -> 45900 | ... V7: =EOMONTH($I$7,COLUMNS($I7:V7)-1) -> 46053 | X7: 45688
B8: Fcst / Act | D8: Tag | F8: Act | G8: Act | H8: Act | I8: Open | J8: Fcst | K8: Fcst | L8: Fcst | M8: Fcst | N8: Fcst | O8: Fcst | P8: Fcst | Q8: Fcst | R8: Fcst | S8: Fcst | T8: Fcst | U8: Fcst | V8: Fcst | X8: 46053
B10: Corporate | D10: SALES | F10: 648 | G10: 717 | H10: 889 | I10: 1212.78 | J10: =SUMIFS(sales_forecast_tbl[Jan-25],sales_forecast_tbl[Toggle],TRUE,sales_forecast_tbl[Category],'P&L_Forecast'!$B10) / Currency_Denominator * (1 + Price_Increase) -> 2490.9797 | K10: =SUMIFS(sales_forecast_tbl[Feb-25],sales_forecast_tbl[Toggle],TRUE,sales_forecast_tbl[Category],'P&L_Forecast'!$B10) / Currency_Denominator * (1 + Price_Increase) -> 3777.8741 | L10: =SUMIFS(sales_forecast_tbl[Mar-25],sales_forecast_tbl[Toggle],TRUE,sales_forecast_tbl[Category],'P&L_Forecast'!$B10) / Currency_Denominator * (1 + Price_Increase) -> 383.8681 | M10: =SUMIFS(sales_forecast_tbl[Apr-25],sales_forecast_tbl[Toggle],TRUE,sales_forecast_tbl[Category],'P&L_Forecast'!$B10) / Currency_Denominator * (1 + Price_Increase) -> 1080.8589 | N10: =SUMIFS(sales_forecast_tbl[May-25],sales_forecast_tbl[Toggle],TRUE,sales_forecast_tbl[Category],'P&L_Forecast'!$B10) / Currency_Denominator * (1 + Price_Increase) -> 639.243 | O10: =SUMIFS(sales_forecast_tbl[Jun-25],sales_forecast_tbl[Toggle],TRUE,sales_forecast_tbl[Category],'P&L_Forecast'!$B10) / Currency_Denominator * (1 + Price_Increase) -> 401.995 | P10: =SUMIFS(sales_forecast_tbl[Jul-25],sales_forecast_tbl[Toggle],TRUE,sales_forecast_tbl[Category],'P&L_Forecast'!$B10) / Currency_Denominator * (1 + Price_Increase) -> 390.841 | Q10: =SUMIFS(sales_forecast_tbl[Aug-25],sales_forecast_tbl[Toggle],TRUE,sales_forecast_tbl[Category],'P&L_Forecast'!$B10) / Currency_Denominator * (1 + Price_Increase) -> 369.2557 | R10: =SUMIFS(sales_forecast_tbl[Sep-25],sales_forecast_tbl[Toggle],TRUE,sales_forecast_tbl[Category],'P&L_Forecast'!$B10) / Currency_Denominator * (1 + Price_Increase) -> 892.0219 | S10: =SUMIFS(sales_forecast_tbl[Oct-25],sales_forecast_tbl[Toggle],TRUE,sales_forecast_tbl[Category],'P&L_Forecast'!$B10) / Currency_Denominator * (1 + Price_Increase) -> 986.656 | T10: =SUMIFS(sales_forecast_tbl[Nov-25],sales_forecast_tbl[Toggle],TRUE,sales_forecast_tbl[Category],'P&L_Forecast'!$B10) / Currency_Denominator * (1 + Price_Increase) -> 1222.815 | U10: =SUMIFS(sales_forecast_tbl[Dec-25],sales_forecast_tbl[Toggle],TRUE,sales_forecast_tbl[Category],'P&L_Forecast'!$B10) / Currency_Denominator * (1 + Price_Increase) -> 1667.5725 | V10: =SUMIFS(sales_forecast_tbl[Jan-26],sales_forecast_tbl[Toggle],TRUE,sales_forecast_tbl[Category],'P&L_Forecast'!$B10) / Currency_Denominator * (1 + Price_Increase) -> 2676.1103 | X10: =SUM(_xlfn.XLOOKUP($X$7,$I$7:W$7,$I10:W10):_xlfn.XLOOKUP($X$8,$I$7:W$7,$I10:W10)) -> 16980.091
B11: Retail | D11: SALES | F11: 111 | G11: 139 | H11: 220 | I11: 365 | J11: =SUMIFS(sales_forecast_tbl[Jan-25],sales_forecast_tbl[Toggle],TRUE,sales_forecast_tbl[Category],'P&L_Forecast'!$B11) / Currency_Denominator * (1 + Price_Increase) -> 648.94462 | K11: =SUMIFS(sales_forecast_tbl[Feb-25],sales_forecast_tbl[Toggle],TRUE,sales_forecast_tbl[Category],'P&L_Forecast'!$B11) / Currency_Denominator * (1 + Price_Increase) -> 730.34457 | L11: =SUMIFS(sales_forecast_tbl[Mar-25],sales_forecast_tbl[Toggle],TRUE,sales_forecast_tbl[Category],'P&L_Forecast'!$B11) / Currency_Denominator * (1 + Price_Increase) -> 157.09679 | M11: =SUMIFS(sales_forecast_tbl[Apr-25],sales_forecast_tbl[Toggle],TRUE,sales_forecast_tbl[Category],'P&L_Forecast'!$B11) / Currency_Denominator * (1 + Price_Increase) -> 456.9839 | N11: =SUMIFS(sales_forecast_tbl[May-25],sales_forecast_tbl[Toggle],TRUE,sales_forecast_tbl[Category],'P&L_Forecast'!$B11) / Currency_Denominator * (1 + Price_Increase) -> 275.71282 | O11: =SUMIFS(sales_forecast_tbl[Jun-25],sales_forecast_tbl[Toggle],TRUE,sales_forecast_tbl[Category],'P&L_Forecast'!$B11) / Currency_Denominator * (1 + Price_Increase) -> 156.156 | P11: =SUMIFS(sales_forecast_tbl[Jul-25],sales_forecast_tbl[Toggle],TRUE,sales_forecast_tbl[Category],'P&L_Forecast'!$B11) / Currency_Denominator * (1 + Price_Increase) -> 153.35992 | Q11: =SUMIFS(sales_forecast_tbl[Aug-25],sales_forecast_tbl[Toggle],TRUE,sales_forecast_tbl[Category],'P&L_Forecast'!$B11) / Currency_Denominator * (1 + Price_Increase) -> 115.10334 | R11: =SUMIFS(sales_forecast_tbl[Sep-25],sales_forecast_tbl[Toggle],TRUE,sales_forecast_tbl[Category],'P&L_Forecast'!$B11) / Currency_Denominator * (1 + Price_Increase) -> 156.64233 | S11: =SUMIFS(sales_forecast_tbl[Oct-25],sales_forecast_tbl[Toggle],TRUE,sales_forecast_tbl[Category],'P&L_Forecast'!$B11) / Currency_Denominator * (1 + Price_Increase) -> 196.4016 | T11: =SUMIFS(sales_forecast_tbl[Nov-25],sales_forecast_tbl[Toggle],TRUE,sales_forecast_tbl[Category],'P&L_Forecast'!$B11) / Currency_Denominator * (1 + Price_Increase) -> 310.44161 | U11: =SUMIFS(sales_forecast_tbl[Dec-25],sales_forecast_tbl[Toggle],TRUE,sales_forecast_tbl[Category],'P&L_Forecast'!$B11) / Currency_Denominator * (1 + Price_Increase) -> 515.89264 | V11: =SUMIFS(sales_forecast_tbl[Jan-26],sales_forecast_tbl[Toggle],TRUE,sales_forecast_tbl[Category],'P&L_Forecast'!$B11) / Currency_Denominator * (1 + Price_Increase) -> 667.95341 | X11: =SUM(_xlfn.XLOOKUP($X$7,$I$7:W$7,$I11:W11):_xlfn.XLOOKUP($X$8,$I$7:W$7,$I11:W11)) -> 4541.0336
B12: eCommerce | D12: SALES | F12: 280.375 | G12: 237.625 | H12: 387.875 | I12: 193.5 | J12: =SUMIFS(sales_forecast_tbl[Jan-25],sales_forecast_tbl[Toggle],TRUE,sales_forecast_tbl[Category],'P&L_Forecast'!$B12) / Currency_Denominator * (1 + Price_Increase) -> 661.0813 | K12: =SUMIFS(sales_forecast_tbl[Feb-25],sales_forecast_tbl[Toggle],TRUE,sales_forecast_tbl[Category],'P&L_Forecast'!$B12) / Currency_Denominator * (1 + Price_Increase) -> 795.54066 | L12: =SUMIFS(sales_forecast_tbl[Mar-25],sales_forecast_tbl[Toggle],TRUE,sales_forecast_tbl[Category],'P&L_Forecast'!$B12) / Currency_Denominator * (1 + Price_Increase) -> 149.28576 | M12: =SUMIFS(sales_forecast_tbl[Apr-25],sales_forecast_tbl[Toggle],TRUE,sales_forecast_tbl[Category],'P&L_Forecast'!$B12) / Currency_Denominator * (1 + Price_Increase) -> 501.43075 | N12: =SUMIFS(sales_forecast_tbl[May-25],sales_forecast_tbl[Toggle],TRUE,sales_forecast_tbl[Category],'P&L_Forecast'!$B12) / Currency_Denominator * (1 + Price_Increase) -> 277.18179 | O12: =SUMIFS(sales_forecast_tbl[Jun-25],sales_forecast_tbl[Toggle],TRUE,sales_forecast_tbl[Category],'P&L_Forecast'!$B12) / Currency_Denominator * (1 + Price_Increase) -> 144.99341 | P12: =SUMIFS(sales_forecast_tbl[Jul-25],sales_forecast_tbl[Toggle],TRUE,sales_forecast_tbl[Category],'P&L_Forecast'!$B12) / Currency_Denominator * (1 + Price_Increase) -> 165.7003 | Q12: =SUMIFS(sales_forecast_tbl[Aug-25],sales_forecast_tbl[Toggle],TRUE,sales_forecast_tbl[Category],'P&L_Forecast'!$B12) / Currency_Denominator * (1 + Price_Increase) -> 114.38297 | R12: =SUMIFS(sales_forecast_tbl[Sep-25],sales_forecast_tbl[Toggle],TRUE,sales_forecast_tbl[Category],'P&L_Forecast'!$B12) / Currency_Denominator * (1 + Price_Increase) -> 158.46242 | S12: =SUMIFS(sales_forecast_tbl[Oct-25],sales_forecast_tbl[Toggle],TRUE,sales_forecast_tbl[Category],'P&L_Forecast'!$B12) / Currency_Denominator * (1 + Price_Increase) -> 196.30428 | T12: =SUMIFS(sales_forecast_tbl[Nov-25],sales_forecast_tbl[Toggle],TRUE,sales_forecast_tbl[Category],'P&L_Forecast'!$B12) / Currency_Denominator * (1 + Price_Increase) -> 330.61068 | U12: =SUMIFS(sales_forecast_tbl[Dec-25],sales_forecast_tbl[Toggle],TRUE,sales_forecast_tbl[Category],'P&L_Forecast'!$B12) / Currency_Denominator * (1 + Price_Increase) -> 535.77394 | V12: =SUMIFS(sales_forecast_tbl[Jan-26],sales_forecast_tbl[Toggle],TRUE,sales_forecast_tbl[Category],'P&L_Forecast'!$B12) / Currency_Denominator * (1 + Price_Increase) -> 747.41912 | X12: =SUM(_xlfn.XLOOKUP($X$7,$I$7:W$7,$I12:W12):_xlfn.XLOOKUP($X$8,$I$7:W$7,$I12:W12)) -> 4778.1674
B14: Total Sales | F14: =SUM(F10:F13) -> 1039.375 | G14: =SUM(G10:G13) -> 1093.625 | H14: =SUM(H10:H13) -> 1496.875 | I14: =SUM(I10:I13) -> 1771.28 | J14: =SUM(J10:J13) -> 3801.0056 | K14: =SUM(K10:K13) -> 5303.7593 | L14: =SUM(L10:L13) -> 690.25065 | M14: =SUM(M10:M13) -> 2039.2736 | ... V14: =SUM(V10:V13) -> 4091.4828 | X14: =SUM(_xlfn.XLOOKUP($X$7,$I$7:W$7,$I14:W14):_xlfn.XLOOKUP($X$8,$I$7:W$7,$I14:W14)) -> 26299.292
B16: Raw Materials | D16: COGS | F16: 333 | G16: 376 | H16: 541 | I16: 809 | J16: =_xlfn.XLOOKUP($B16,Cost_Expense_Fcst!$B$7:$B$9,Cost_Expense_Fcst!O$7:O$9)*J$14 / (1 + Price_Increase) -> 1624.066 | K16: =_xlfn.XLOOKUP($B16,Cost_Expense_Fcst!$B$7:$B$9,Cost_Expense_Fcst!P$7:P$9)*K$14 / (1 + Price_Increase) -> 2266.1517 | L16: =_xlfn.XLOOKUP($B16,Cost_Expense_Fcst!$B$7:$B$9,Cost_Expense_Fcst!Q$7:Q$9)*L$14 / (1 + Price_Increase) -> 294.92528 | M16: =_xlfn.XLOOKUP($B16,Cost_Expense_Fcst!$B$7:$B$9,Cost_Expense_Fcst!R$7:R$9)*M$14 / (1 + Price_Increase) -> 871.32597 | N16: =_xlfn.XLOOKUP($B16,Cost_Expense_Fcst!$B$7:$B$9,Cost_Expense_Fcst!S$7:S$9)*N$14 / (1 + Price_Increase) -> 509.36789 | O16: =_xlfn.XLOOKUP($B16,Cost_Expense_Fcst!$B$7:$B$9,Cost_Expense_Fcst!T$7:T$9)*O$14 / (1 + Price_Increase) -> 300.43443 | P16: =_xlfn.XLOOKUP($B16,Cost_Expense_Fcst!$B$7:$B$9,Cost_Expense_Fcst!U$7:U$9)*P$14 / (1 + Price_Increase) -> 303.32143 | Q16: =_xlfn.XLOOKUP($B16,Cost_Expense_Fcst!$B$7:$B$9,Cost_Expense_Fcst!V$7:V$9)*Q$14 / (1 + Price_Increase) -> 255.82613 | ... V16: =_xlfn.XLOOKUP($B16,Cost_Expense_Fcst!$B$7:$B$9,Cost_Expense_Fcst!AA$7:AA$9)*V$14 / (1 + Price_Increase) -> 1748.179 | X16: =SUM(_xlfn.XLOOKUP($X$7,$I$7:W$7,$I16:W16):_xlfn.XLOOKUP($X$8,$I$7:W$7,$I16:W16)) -> 11236.97
B17: Direct Labor | D17: DL | F17: 102 | G17: 115 | H17: 166 | I17: 249 | J17: =_xlfn.XLOOKUP($B17,Cost_Expense_Fcst!$B$7:$B$9,Cost_Expense_Fcst!O$7:O$9)*J$14 / (1 + Price_Increase) -> 587.42814 | K17: =_xlfn.XLOOKUP($B17,Cost_Expense_Fcst!$B$7:$B$9,Cost_Expense_Fcst!P$7:P$9)*K$14 / (1 + Price_Increase) -> 819.6719 | L17: =_xlfn.XLOOKUP($B17,Cost_Expense_Fcst!$B$7:$B$9,Cost_Expense_Fcst!Q$7:Q$9)*L$14 / (1 + Price_Increase) -> 106.6751 | M17: =_xlfn.XLOOKUP($B17,Cost_Expense_Fcst!$B$7:$B$9,Cost_Expense_Fcst!R$7:R$9)*M$14 / (1 + Price_Increase) -> 315.16046 | N17: =_xlfn.XLOOKUP($B17,Cost_Expense_Fcst!$B$7:$B$9,Cost_Expense_Fcst!S$7:S$9)*N$14 / (1 + Price_Increase) -> 184.23945 | O17: =_xlfn.XLOOKUP($B17,Cost_Expense_Fcst!$B$7:$B$9,Cost_Expense_Fcst!T$7:T$9)*O$14 / (1 + Price_Increase) -> 108.66777 | P17: =_xlfn.XLOOKUP($B17,Cost_Expense_Fcst!$B$7:$B$9,Cost_Expense_Fcst!U$7:U$9)*P$14 / (1 + Price_Increase) -> 109.71201 | Q17: =_xlfn.XLOOKUP($B17,Cost_Expense_Fcst!$B$7:$B$9,Cost_Expense_Fcst!V$7:V$9)*Q$14 / (1 + Price_Increase) -> 92.532857 | ... V17: =_xlfn.XLOOKUP($B17,Cost_Expense_Fcst!$B$7:$B$9,Cost_Expense_Fcst!AA$7:AA$9)*V$14 / (1 + Price_Increase) -> 632.32007 | X17: =SUM(_xlfn.XLOOKUP($X$7,$I$7:W$7,$I17:W17):_xlfn.XLOOKUP($X$8,$I$7:W$7,$I17:W17)) -> 4064.4361
B18: Mfg OH | D18: COGS | F18: 77 | G18: 86 | H18: 125 | I18: 186 | J18: =_xlfn.XLOOKUP($B18,Cost_Expense_Fcst!$B$7:$B$9,Cost_Expense_Fcst!O$7:O$9)*J$14 / (1 + Price_Increase) -> 345.54597 | K18: =_xlfn.XLOOKUP($B18,Cost_Expense_Fcst!$B$7:$B$9,Cost_Expense_Fcst!P$7:P$9)*K$14 / (1 + Price_Increase) -> 482.15994 | L18: =_xlfn.XLOOKUP($B18,Cost_Expense_Fcst!$B$7:$B$9,Cost_Expense_Fcst!Q$7:Q$9)*L$14 / (1 + Price_Increase) -> 62.750059 | M18: =_xlfn.XLOOKUP($B18,Cost_Expense_Fcst!$B$7:$B$9,Cost_Expense_Fcst!R$7:R$9)*M$14 / (1 + Price_Increase) -> 185.3885 | N18: =_xlfn.XLOOKUP($B18,Cost_Expense_Fcst!$B$7:$B$9,Cost_Expense_Fcst!S$7:S$9)*N$14 / (1 + Price_Increase) -> 108.37615 | O18: =_xlfn.XLOOKUP($B18,Cost_Expense_Fcst!$B$7:$B$9,Cost_Expense_Fcst!T$7:T$9)*O$14 / (1 + Price_Increase) -> 63.922219 | P18: =_xlfn.XLOOKUP($B18,Cost_Expense_Fcst!$B$7:$B$9,Cost_Expense_Fcst!U$7:U$9)*P$14 / (1 + Price_Increase) -> 64.536474 | Q18: =_xlfn.XLOOKUP($B18,Cost_Expense_Fcst!$B$7:$B$9,Cost_Expense_Fcst!V$7:V$9)*Q$14 / (1 + Price_Increase) -> 54.431092 | ... V18: =_xlfn.XLOOKUP($B18,Cost_Expense_Fcst!$B$7:$B$9,Cost_Expense_Fcst!AA$7:AA$9)*V$14 / (1 + Price_Increase) -> 371.95298 | X18: =SUM(_xlfn.XLOOKUP($X$7,$I$7:W$7,$I18:W18):_xlfn.XLOOKUP($X$8,$I$7:W$7,$I18:W18)) -> 2390.8447
B20: Total COGS | F20: =SUM(F16:F19) -> 512 | G20: =SUM(G16:G19) -> 577 | H20: =SUM(H16:H19) -> 832 | I20: =SUM(I16:I19) -> 1244 | J20: =SUM(J16:J19) -> 2557.0401 | K20: =SUM(K16:K19) -> 3567.9835 | L20: =SUM(L16:L19) -> 464.35044 | M20: =SUM(M16:M19) -> 1371.8749 | ... V20: =SUM(V16:V19) -> 2752.4521 | X20: =SUM(_xlfn.XLOOKUP($X$7,$I$7:W$7,$I20:W20):_xlfn.XLOOKUP($X$8,$I$7:W$7,$I20:W20)) -> 17692.251
B22: Gross Profit | F22: =F14-F20 -> 527.375 | G22: =G14-G20 -> 516.625 | H22: =H14-H20 -> 664.875 | I22: =I14-I20 -> 527.28 | J22: =J14-J20 -> 1243.9655 | K22: =K14-K20 -> 1735.7758 | L22: =L14-L20 -> 225.90021 | M22: =M14-M20 -> 667.39862 | ... V22: =V14-V20 -> 1339.0307 | X22: =SUM(_xlfn.XLOOKUP($X$7,$I$7:W$7,$I22:W22):_xlfn.XLOOKUP($X$8,$I$7:W$7,$I22:W22)) -> 8607.0411
B23: Gross Margin % | F23: =F22/F$14 -> 0.50739627 | G23: =G22/G$14 -> 0.47239685 | H23: =H22/H$14 -> 0.44417537 | I23: =I22/I$14 -> 0.29768303 | J23: =J22/J$14 -> 0.32727273 | K23: =K22/K$14 -> 0.32727273 | L23: =L22/L$14 -> 0.32727273 | M23: =M22/M$14 -> 0.32727273 | ... V23: =V22/V$14 -> 0.32727273 | X23: =X22/X$14 -> 0.32727273
B25: Salaries (net) | D25: SGA | F25: 90.34 | G25: 90.34 | H25: 90.34 | I25: 90.34 | J25: =SUM(INDEX(payroll_schedule_tbl[[1/31/2025]:[12/31/2025]], 0, MATCH(TEXT('P&L_Forecast'!J7, "m/d/yyyy"), payroll_schedule_tbl[[#Headers],[1/31/2025]:[12/31/2025]], 0))) / Currency_Denominator -> 173.91 | K25: =SUM(INDEX(payroll_schedule_tbl[[1/31/2025]:[12/31/2025]], 0, MATCH(TEXT('P&L_Forecast'!K7, "m/d/yyyy"), payroll_schedule_tbl[[#Headers],[1/31/2025]:[12/31/2025]], 0))) / Currency_Denominator -> 173.91 | L25: =SUM(INDEX(payroll_schedule_tbl[[1/31/2025]:[12/31/2025]], 0, MATCH(TEXT('P&L_Forecast'!L7, "m/d/yyyy"), payroll_schedule_tbl[[#Headers],[1/31/2025]:[12/31/2025]], 0))) / Currency_Denominator -> 173.91 | M25: =SUM(INDEX(payroll_schedule_tbl[[1/31/2025]:[12/31/2025]], 0, MATCH(TEXT('P&L_Forecast'!M7, "m/d/yyyy"), payroll_schedule_tbl[[#Headers],[1/31/2025]:[12/31/2025]], 0))) / Currency_Denominator -> 178.86 | N25: =SUM(INDEX(payroll_schedule_tbl[[1/31/2025]:[12/31/2025]], 0, MATCH(TEXT('P&L_Forecast'!N7, "m/d/yyyy"), payroll_schedule_tbl[[#Headers],[1/31/2025]:[12/31/2025]], 0))) / Currency_Denominator -> 182.5725 | O25: =SUM(INDEX(payroll_schedule_tbl[[1/31/2025]:[12/31/2025]], 0, MATCH(TEXT('P&L_Forecast'!O7, "m/d/yyyy"), payroll_schedule_tbl[[#Headers],[1/31/2025]:[12/31/2025]], 0))) / Currency_Denominator -> 197.4225 | P25: =SUM(INDEX(payroll_schedule_tbl[[1/31/2025]:[12/31/2025]], 0, MATCH(TEXT('P&L_Forecast'!P7, "m/d/yyyy"), payroll_schedule_tbl[[#Headers],[1/31/2025]:[12/31/2025]], 0))) / Currency_Denominator -> 200.7225 | Q25: =SUM(INDEX(payroll_schedule_tbl[[1/31/2025]:[12/31/2025]], 0, MATCH(TEXT('P&L_Forecast'!Q7, "m/d/yyyy"), payroll_schedule_tbl[[#Headers],[1/31/2025]:[12/31/2025]], 0))) / Currency_Denominator -> 211.86 | ... U25: =SUM(INDEX(payroll_schedule_tbl[[1/31/2025]:[12/31/2025]], 0, MATCH(TEXT('P&L_Forecast'!U7, "m/d/yyyy"), payroll_schedule_tbl[[#Headers],[1/31/2025]:[12/31/2025]], 0))) / Currency_Denominator -> 209.7975 | V25: =SUM(INDEX(payroll_schedule_tbl[[1/31/2025]:[1/31/2026]], 0, MATCH(TEXT('P&L_Forecast'!V7, "m/d/yyyy"), payroll_schedule_tbl[[#Headers],[1/31/2025]:[1/31/2026]], 0))) / Currency_Denominator -> 209.7975 | X25: =SUM(_xlfn.XLOOKUP($X$7,$I$7:W$7,$I25:W25):_xlfn.XLOOKUP($X$8,$I$7:W$7,$I25:W25)) -> 2544.2175
B26: Bonuses | D26: SGA | F26: 13 | G26: 14 | H26: 14 | I26: 14 | J26: =INDEX(bonus_accrual_forecast_tbl[#Totals],1,MATCH(TEXT('P&L_Forecast'!J7, "m/d/yyyy"),bonus_accrual_forecast_tbl[#Headers],0)) / Currency_Denominator -> 25.41825 | K26: =INDEX(bonus_accrual_forecast_tbl[#Totals],1,MATCH(TEXT('P&L_Forecast'!K7, "m/d/yyyy"),bonus_accrual_forecast_tbl[#Headers],0)) / Currency_Denominator -> 25.41825 | L26: =INDEX(bonus_accrual_forecast_tbl[#Totals],1,MATCH(TEXT('P&L_Forecast'!L7, "m/d/yyyy"),bonus_accrual_forecast_tbl[#Headers],0)) / Currency_Denominator -> 25.41825 | M26: =INDEX(bonus_accrual_forecast_tbl[#Totals],1,MATCH(TEXT('P&L_Forecast'!M7, "m/d/yyyy"),bonus_accrual_forecast_tbl[#Headers],0)) / Currency_Denominator -> 26.767125 | N26: =INDEX(bonus_accrual_forecast_tbl[#Totals],1,MATCH(TEXT('P&L_Forecast'!N7, "m/d/yyyy"),bonus_accrual_forecast_tbl[#Headers],0)) / Currency_Denominator -> 27.602438 | O26: =INDEX(bonus_accrual_forecast_tbl[#Totals],1,MATCH(TEXT('P&L_Forecast'!O7, "m/d/yyyy"),bonus_accrual_forecast_tbl[#Headers],0)) / Currency_Denominator -> 31.421009 | P26: =INDEX(bonus_accrual_forecast_tbl[#Totals],1,MATCH(TEXT('P&L_Forecast'!P7, "m/d/yyyy"),bonus_accrual_forecast_tbl[#Headers],0)) / Currency_Denominator -> 33.772259 | Q26: =INDEX(bonus_accrual_forecast_tbl[#Totals],1,MATCH(TEXT('P&L_Forecast'!Q7, "m/d/yyyy"),bonus_accrual_forecast_tbl[#Headers],0)) / Currency_Denominator -> 37.781759 | ... V26: =INDEX(bonus_accrual_forecast_tbl[#Totals],1,MATCH(TEXT('P&L_Forecast'!V7, "m/d/yyyy"),bonus_accrual_forecast_tbl[#Headers],0)) / Currency_Denominator -> 38.744357 | X26: =SUM(_xlfn.XLOOKUP($X$7,$I$7:W$7,$I26:W26):_xlfn.XLOOKUP($X$8,$I$7:W$7,$I26:W26)) -> 436.46448
B27: Rent | D27: SGA | F27: 2.5 | G27: 2.5 | H27: 2.5 | I27: 2.5 | J27: =Cost_Expense_Fcst!O18 / Currency_Denominator -> 25 | K27: =Cost_Expense_Fcst!P18 / Currency_Denominator -> 25 | L27: =Cost_Expense_Fcst!Q18 / Currency_Denominator -> 25 | M27: =Cost_Expense_Fcst!R18 / Currency_Denominator -> 25 | N27: =Cost_Expense_Fcst!S18 / Currency_Denominator -> 25 | O27: =Cost_Expense_Fcst!T18 / Currency_Denominator -> 25 | P27: =Cost_Expense_Fcst!U18 / Currency_Denominator -> 25 | Q27: =Cost_Expense_Fcst!V18 / Currency_Denominator -> 25 | ... W27: =Cost_Expense_Fcst!AB18 / Currency_Denominator -> 0 | X27: =SUM(_xlfn.XLOOKUP($X$7,$I$7:W$7,$I27:W27):_xlfn.XLOOKUP($X$8,$I$7:W$7,$I27:W27)) -> 325
B28: Utilities | D28: SGA | F28: 9.75 | G28: 9.75 | H28: 9.75 | I28: 9.75 | J28: =Cost_Expense_Fcst!O28 / Currency_Denominator -> 38.012951 | K28: =Cost_Expense_Fcst!P28 / Currency_Denominator -> 53.041633 | L28: =Cost_Expense_Fcst!Q28 / Currency_Denominator -> 14.0625 | M28: =Cost_Expense_Fcst!R28 / Currency_Denominator -> 20.394289 | N28: =Cost_Expense_Fcst!S28 / Currency_Denominator -> 14.0625 | O28: =Cost_Expense_Fcst!T28 / Currency_Denominator -> 14.0625 | P28: =Cost_Expense_Fcst!U28 / Currency_Denominator -> 14.0625 | Q28: =Cost_Expense_Fcst!V28 / Currency_Denominator -> 14.0625 | ... W28: =Cost_Expense_Fcst!AB28 / Currency_Denominator -> 0 | X28: =SUM(_xlfn.XLOOKUP($X$7,$I$7:W$7,$I28:W28):_xlfn.XLOOKUP($X$8,$I$7:W$7,$I28:W28)) -> 296.63887
B29: Marketing | D29: SGA | F29: 48 | G29: 48 | H29: 49 | I29: 50 | J29: =Cost_Expense_Fcst!O36 / Currency_Denominator -> 39.36594 | K29: =Cost_Expense_Fcst!P36 / Currency_Denominator -> 54.220336 | L29: =Cost_Expense_Fcst!Q36 / Currency_Denominator -> 7.056433 | M29: =Cost_Expense_Fcst!R36 / Currency_Denominator -> 20.847495 | N29: =Cost_Expense_Fcst!S36 / Currency_Denominator -> 12.187224 | O29: =Cost_Expense_Fcst!T36 / Currency_Denominator -> 7.1882459 | P29: =Cost_Expense_Fcst!U36 / Currency_Denominator -> 7.2573207 | Q29: =Cost_Expense_Fcst!V36 / Currency_Denominator -> 6.1209401 | ... W29: =Cost_Expense_Fcst!AB36 / Currency_Denominator -> 0 | X29: =SUM(_xlfn.XLOOKUP($X$7,$I$7:W$7,$I29:W29):_xlfn.XLOOKUP($X$8,$I$7:W$7,$I29:W29)) -> 269.36594
B31: Pretax Income | F31: =F22-SUM(F25:F30) -> 363.785 | G31: =G22-SUM(G25:G30) -> 352.035 | H31: =H22-SUM(H25:H30) -> 499.285 | I31: =I22-SUM(I25:I30) -> 360.69 | J31: =J22-SUM(J25:J30) -> 942.25834 | K31: =K22-SUM(K25:K30) -> 1404.1856 | L31: =L22-SUM(L25:L30) -> -19.546969 | M31: =M22-SUM(M25:M30) -> 395.52971 | ... V31: =V22-SUM(V25:V30) -> 982.7437 | X31: =SUM(_xlfn.XLOOKUP($X$7,$I$7:W$7,$I31:W31):_xlfn.XLOOKUP($X$8,$I$7:W$7,$I31:W31)) -> 4735.3543
B33: Tax (Benefit) / Expense | D33: TAX | F33: =F31*Tax_Rate -> 123.6869 | G33: =G31*Tax_Rate -> 119.6919 | H33: =H31*Tax_Rate -> 169.7569 | I33: =I31*Tax_Rate -> 122.6346 | J33: =J31*Tax_Rate -> 320.36783 | K33: =K31*Tax_Rate -> 477.42309 | L33: =L31*Tax_Rate -> -6.6459694 | M33: =M31*Tax_Rate -> 134.4801 | ... V33: =V31*Tax_Rate -> 334.13286 | X33: =SUM(_xlfn.XLOOKUP($X$7,$I$7:W$7,$I33:W33):_xlfn.XLOOKUP($X$8,$I$7:W$7,$I33:W33)) -> 1610.0205
B35: Net Income | F35: =F31-SUM(F33:F34) -> 240.0981 | G35: =G31-SUM(G33:G34) -> 232.3431 | H35: =H31-SUM(H33:H34) -> 329.5281 | I35: =I31-SUM(I33:I34) -> 238.0554 | J35: =J31-SUM(J33:J34) -> 621.8905 | K35: =K31-SUM(K33:K34) -> 926.76247 | L35: =L31-SUM(L33:L34) -> -12.900999 | M35: =M31-SUM(M33:M34) -> 261.04961 | ... V35: =V31-SUM(V33:V34) -> 648.61085 | X35: =SUM(_xlfn.XLOOKUP($X$7,$I$7:W$7,$I35:W35):_xlfn.XLOOKUP($X$8,$I$7:W$7,$I35:W35)) -> 3125.3338
B36: Net Margin % | F36: =F35/F$14 -> 0.23100238 | G36: =G35/G$14 -> 0.21245226 | H36: =H35/H$14 -> 0.22014403 | I36: =I35/I$14 -> 0.13439738 | J36: =J35/J$14 -> 0.1636121 | K36: =K35/K$14 -> 0.1747369 | L36: =L35/L$14 -> -0.018690311 | M36: =M35/M$14 -> 0.12801108 | ... V36: =V35/V$14 -> 0.15852709 | X36: =X35/X$14 -> 0.11883718
B43: Accounts Receivable
B45: A/R Beg. Bal. | J45: =I51 -> 5269.4025 | K45: =J51 -> 4281.5362 | L45: =K51 -> 9104.765 | M45: =L51 -> 6108.0402 | N45: =M51 -> 3002.6672 | O45: =N51 -> 3525.2616 | P45: =O51 -> 2250.3107 | Q45: =P51 -> 1803.8384 | ... V45: =U51 -> 5111.8475 | X45: =J45 -> 5269.4025
B46: + Sales | D46: Sales | J46: =SUMIFS(J$9:J$39,$D$9:$D$39,$D46) -> 3801.0056 | K46: =SUMIFS(K$9:K$39,$D$9:$D$39,$D46) -> 5303.7593 | L46: =SUMIFS(L$9:L$39,$D$9:$D$39,$D46) -> 690.25065 | M46: =SUMIFS(M$9:M$39,$D$9:$D$39,$D46) -> 2039.2736 | N46: =SUMIFS(N$9:N$39,$D$9:$D$39,$D46) -> 1192.1376 | O46: =SUMIFS(O$9:O$39,$D$9:$D$39,$D46) -> 703.14441 | P46: =SUMIFS(P$9:P$39,$D$9:$D$39,$D46) -> 709.90122 | Q46: =SUMIFS(Q$9:Q$39,$D$9:$D$39,$D46) -> 598.74201 | ... V46: =SUMIFS(V$9:V$39,$D$9:$D$39,$D46) -> 4091.4828 | X46: =SUM(J46:W46) -> 26299.292
B47: - Receipts on Aged A/R | J47: =-SUMIFS(AR_aging_tbl[AR_Aging],AR_aging_tbl[Receipt_Date],">"&'P&L_Forecast'!I$7,AR_aging_tbl[Receipt_Date],"<="&'P&L_Forecast'!J$7) / Currency_Denominator -> -4788.8719 | K47: =-SUMIFS(AR_aging_tbl[AR_Aging],AR_aging_tbl[Receipt_Date],">"&'P&L_Forecast'!J$7,AR_aging_tbl[Receipt_Date],"<="&'P&L_Forecast'!K$7) / Currency_Denominator -> -480.53057 | L47: =-SUMIFS(AR_aging_tbl[AR_Aging],AR_aging_tbl[Receipt_Date],">"&'P&L_Forecast'!K$7,AR_aging_tbl[Receipt_Date],"<="&'P&L_Forecast'!L$7) / Currency_Denominator -> 0 | M47: =-SUMIFS(AR_aging_tbl[AR_Aging],AR_aging_tbl[Receipt_Date],">"&'P&L_Forecast'!L$7,AR_aging_tbl[Receipt_Date],"<="&'P&L_Forecast'!M$7) / Currency_Denominator -> 0 | N47: =-SUMIFS(AR_aging_tbl[AR_Aging],AR_aging_tbl[Receipt_Date],">"&'P&L_Forecast'!M$7,AR_aging_tbl[Receipt_Date],"<="&'P&L_Forecast'!N$7) / Currency_Denominator -> 0 | O47: =-SUMIFS(AR_aging_tbl[AR_Aging],AR_aging_tbl[Receipt_Date],">"&'P&L_Forecast'!N$7,AR_aging_tbl[Receipt_Date],"<="&'P&L_Forecast'!O$7) / Currency_Denominator -> 0 | P47: =-SUMIFS(AR_aging_tbl[AR_Aging],AR_aging_tbl[Receipt_Date],">"&'P&L_Forecast'!O$7,AR_aging_tbl[Receipt_Date],"<="&'P&L_Forecast'!P$7) / Currency_Denominator -> 0 | Q47: =-SUMIFS(AR_aging_tbl[AR_Aging],AR_aging_tbl[Receipt_Date],">"&'P&L_Forecast'!P$7,AR_aging_tbl[Receipt_Date],"<="&'P&L_Forecast'!Q$7) / Currency_Denominator -> 0 | ... V47: =-SUMIFS(AR_aging_tbl[AR_Aging],AR_aging_tbl[Receipt_Date],">"&'P&L_Forecast'!U$7,AR_aging_tbl[Receipt_Date],"<="&'P&L_Forecast'!V$7) / Currency_Denominator -> 0 | X47: =SUM(J47:W47) -> -5269.4025
B48: - Receipts on New Sales | J48: =-(SUMIFS($E46:J46,$E155:J155,J$7)+SUMIFS($E53:J53,$E155:J155,J$7)) -> 0 | K48: =-(SUMIFS($E46:K46,$E155:K155,K$7)+SUMIFS($E53:K53,$E155:K155,K$7)) -> 0 | L48: =-(SUMIFS($E46:L46,$E155:L155,L$7)+SUMIFS($E53:L53,$E155:L155,L$7)) -> -3686.9755 | M48: =-(SUMIFS($E46:M46,$E155:M155,M$7)+SUMIFS($E53:M53,$E155:M155,M$7)) -> -5144.6466 | N48: =-(SUMIFS($E46:N46,$E155:N155,N$7)+SUMIFS($E53:N53,$E155:N155,N$7)) -> -669.54313 | O48: =-(SUMIFS($E46:O46,$E155:O155,O$7)+SUMIFS($E53:O53,$E155:O155,O$7)) -> -1978.0953 | P48: =-(SUMIFS($E46:P46,$E155:P155,P$7)+SUMIFS($E53:P53,$E155:P155,P$7)) -> -1156.3735 | Q48: =-(SUMIFS($E46:Q46,$E155:Q155,Q$7)+SUMIFS($E53:Q53,$E155:Q155,Q$7)) -> -682.05008 | ... V48: =-(SUMIFS($E46:V46,$E155:V155,V$7)+SUMIFS($E53:V53,$E155:V155,V$7)) -> -1807.9513 | X48: =SUM(J48:W48) -> -18903.913
B49: - Receipts on Uncollectables | J49: =(I54+J53)*J55 -> 0 | K49: =(J54+K53)*K55 -> 0 | L49: =(K54+L53)*L55 -> 0 | M49: =(L54+M53)*M55 -> 0 | N49: =(M54+N53)*N55 -> 0 | O49: =(N54+O53)*O55 -> 0 | P49: =(O54+P53)*P55 -> 0 | Q49: =(P54+Q53)*Q55 -> 0 | ... V49: =(U54+V53)*V55 -> 0 | X49: =SUM(J49:W49) -> 0
B51: A/R End. Bal. | I51: =AR_aging_tbl[[#Totals],[AR_Aging]]/Currency_Denominator -> 5269.4025 | J51: =SUM(J45:J50) -> 4281.5362 | K51: =SUM(K45:K50) -> 9104.765 | L51: =SUM(L45:L50) -> 6108.0402 | M51: =SUM(M45:M50) -> 3002.6672 | N51: =SUM(N45:N50) -> 3525.2616 | O51: =SUM(O45:O50) -> 2250.3107 | P51: =SUM(P45:P50) -> 1803.8384 | Q51: =SUM(Q45:Q50) -> 1720.5304 | ... V51: =SUM(V45:V50) -> 7395.379 | X51: =SUM(X45:X50) -> 7395.379
B53: ="Uncollectable Reserve ("&TEXT(Assumptions!$C$16,"#0.0%")&")" -> Uncollectable Reserve (3.0%) | J53: =-J46*Assumptions!$C$16 -> -114.03017 | K53: =-K46*Assumptions!$C$16 -> -159.11278 | L53: =-L46*Assumptions!$C$16 -> -20.70752 | M53: =-M46*Assumptions!$C$16 -> -61.178207 | N53: =-N46*Assumptions!$C$16 -> -35.764128 | O53: =-O46*Assumptions!$C$16 -> -21.094332 | P53: =-P46*Assumptions!$C$16 -> -21.297036 | Q53: =-Q46*Assumptions!$C$16 -> -17.96226 | ... V53: =-V46*Assumptions!$C$16 -> -122.74448 | X53: =SUM(J53:W53) -> -788.97876
B54: ="Cumulative Uncollectable Reserve ("&TEXT(Assumptions!$C$16,"#0.0%")&")" -> Cumulative Uncollectable Reserve (3.0%) | J54: =(J53+I54)*NOT(J55) -> -114.03017 | K54: =(K53+J54)*NOT(K55) -> -273.14295 | L54: =(L53+K54)*NOT(L55) -> -293.85047 | M54: =(M53+L54)*NOT(M55) -> -355.02867 | N54: =(N53+M54)*NOT(N55) -> -390.7928 | O54: =(O53+N54)*NOT(O55) -> -411.88714 | P54: =(P53+O54)*NOT(P55) -> -433.18417 | Q54: =(Q53+P54)*NOT(Q55) -> -451.14643 | ... V54: =(V53+U54)*NOT(V55) -> -788.97876 | X54: =V54 -> -788.97876
B55: Collect Reserve? | J55: FALSE | K55: FALSE | L55: FALSE | M55: FALSE | N55: FALSE | O55: FALSE | P55: FALSE | Q55: FALSE | R55: FALSE | S55: FALSE | T55: FALSE | U55: FALSE | V55: FALSE
B57: Accounts Payable
B59: A/P Beg. Bal. | J59: =I64 -> 2871.11 | K59: =J64 -> 1969.612 | L59: =K64 -> 2748.3117 | M59: =L64 -> 357.67534 | N59: =M64 -> 1056.7145 | O59: =N64 -> 617.74404 | P59: =O64 -> 364.35665 | Q59: =P64 -> 367.8579 | ... V59: =U64 -> 1409.0603 | X59: =J59 -> 2871.11
B60: + Costs | D60: COGS | J60: =SUMIFS(J$9:J$39,$D$9:$D$39,$D60) -> 1969.612 | K60: =SUMIFS(K$9:K$39,$D$9:$D$39,$D60) -> 2748.3117 | L60: =SUMIFS(L$9:L$39,$D$9:$D$39,$D60) -> 357.67534 | M60: =SUMIFS(M$9:M$39,$D$9:$D$39,$D60) -> 1056.7145 | N60: =SUMIFS(N$9:N$39,$D$9:$D$39,$D60) -> 617.74404 | O60: =SUMIFS(O$9:O$39,$D$9:$D$39,$D60) -> 364.35665 | P60: =SUMIFS(P$9:P$39,$D$9:$D$39,$D60) -> 367.8579 | Q60: =SUMIFS(Q$9:Q$39,$D$9:$D$39,$D60) -> 310.25723 | ... V60: =SUMIFS(V$9:V$39,$D$9:$D$39,$D60) -> 2120.132 | X60: =SUM(J60:W60) -> 13627.815
B61: - Payments on Aged A/P | J61: =-SUMIFS(AP_aging_tbl[AP_Aging],AP_aging_tbl[Pay_Date],">"&'P&L_Forecast'!I$7,AP_aging_tbl[Pay_Date],"<="&'P&L_Forecast'!J$7) / Currency_Denominator -> -2871.11 | K61: =-SUMIFS(AP_aging_tbl[AP_Aging],AP_aging_tbl[Pay_Date],">"&'P&L_Forecast'!J$7,AP_aging_tbl[Pay_Date],"<="&'P&L_Forecast'!K$7) / Currency_Denominator -> 0 | L61: =-SUMIFS(AP_aging_tbl[AP_Aging],AP_aging_tbl[Pay_Date],">"&'P&L_Forecast'!K$7,AP_aging_tbl[Pay_Date],"<="&'P&L_Forecast'!L$7) / Currency_Denominator -> 0 | M61: =-SUMIFS(AP_aging_tbl[AP_Aging],AP_aging_tbl[Pay_Date],">"&'P&L_Forecast'!L$7,AP_aging_tbl[Pay_Date],"<="&'P&L_Forecast'!M$7) / Currency_Denominator -> 0 | N61: =-SUMIFS(AP_aging_tbl[AP_Aging],AP_aging_tbl[Pay_Date],">"&'P&L_Forecast'!M$7,AP_aging_tbl[Pay_Date],"<="&'P&L_Forecast'!N$7) / Currency_Denominator -> 0 | O61: =-SUMIFS(AP_aging_tbl[AP_Aging],AP_aging_tbl[Pay_Date],">"&'P&L_Forecast'!N$7,AP_aging_tbl[Pay_Date],"<="&'P&L_Forecast'!O$7) / Currency_Denominator -> 0 | P61: =-SUMIFS(AP_aging_tbl[AP_Aging],AP_aging_tbl[Pay_Date],">"&'P&L_Forecast'!O$7,AP_aging_tbl[Pay_Date],"<="&'P&L_Forecast'!P$7) / Currency_Denominator -> 0 | Q61: =-SUMIFS(AP_aging_tbl[AP_Aging],AP_aging_tbl[Pay_Date],">"&'P&L_Forecast'!P$7,AP_aging_tbl[Pay_Date],"<="&'P&L_Forecast'!Q$7) / Currency_Denominator -> 0 | ... V61: =-SUMIFS(AP_aging_tbl[AP_Aging],AP_aging_tbl[Pay_Date],">"&'P&L_Forecast'!U$7,AP_aging_tbl[Pay_Date],"<="&'P&L_Forecast'!V$7) / Currency_Denominator -> 0 | X61: =SUM(J61:W61) -> -2871.11
...

Sheet Support_Schedules>

Sheet Sales_Forecast
B1: {=Company_Name} -> Pinnacle Supplier DBA Candy Confection
B2: Sales Forecast
B3: All figures in USD
B5: Customer Name | C5: Category | D5: Toggle | E5: Jan-25 | F5: Feb-25 | G5: Mar-25 | H5: Apr-25 | I5: May-25 | J5: Jun-25 | K5: Jul-25 | L5: Aug-25 | M5: Sep-25 | N5: Oct-25 | O5: Nov-25 | P5: Dec-25 | Q5: Jan-26 | R5: Total | S5: % of Total
B6: Apex Foods Inc. | C6: Corporate | D6: {=_xlfn.XLOOKUP(sales_forecast_tbl[[#This Row],[Customer Name]],_xlfn.ANCHORARRAY(Assumptions!$C$34),Assumptions!$D$34:$D$107)} -> TRUE | E6: 4242 | F6: 4666 | G6: 977 | H6: 2929 | I6: 1677 | J6: 984 | K6: 994 | L6: 739 | M6: 969 | N6: 1220 | O6: 1915 | P6: 3181 | Q6: 3898.6306 | R6: =SUM(sales_forecast_tbl[[#This Row],[Feb-25]:[Jan-26]]) -> 24149.631 | S6: =sales_forecast_tbl[[#This Row],[Total]]/sales_forecast_tbl[[#Totals],[Total]] -> 0.0011807385 | Y6: 0.91905484
B7: Beacon Confections | C7: Corporate | D7: {=_xlfn.XLOOKUP(sales_forecast_tbl[[#This Row],[Customer Name]],_xlfn.ANCHORARRAY(Assumptions!$C$34),Assumptions!$D$34:$D$107)} -> TRUE | E7: 3759 | F7: 4244 | G7: 899 | H7: 2699 | I7: 1519 | J7: 871 | K7: 879 | L7: 639 | M7: 857 | N7: 1071 | O7: 1697 | P7: 2771 | Q7: 3955.0734 | R7: =SUM(sales_forecast_tbl[[#This Row],[Feb-25]:[Jan-26]]) -> 22101.073 | S7: =sales_forecast_tbl[[#This Row],[Total]]/sales_forecast_tbl[[#Totals],[Total]] -> 0.0010805792 | Y7: 1.0521611
B8: Summit Gourmet Supply | C8: Corporate | D8: {=_xlfn.XLOOKUP(sales_forecast_tbl[[#This Row],[Customer Name]],_xlfn.ANCHORARRAY(Assumptions!$C$34),Assumptions!$D$34:$D$107)} -> TRUE | E8: 4011 | F8: 4539 | G8: 960 | H8: 2881 | I8: 1643 | J8: 967 | K8: 925 | L8: 710 | M8: 963 | N8: 1170 | O8: 1957 | P8: 3159 | Q8: 4517.3314 | R8: =SUM(sales_forecast_tbl[[#This Row],[Feb-25]:[Jan-26]]) -> 24391.331 | S8: =sales_forecast_tbl[[#This Row],[Total]]/sales_forecast_tbl[[#Totals],[Total]] -> 0.0011925559 | Y8: 1.1262357
B9: Sterling Fine Foods | C9: Corporate | D9: {=_xlfn.XLOOKUP(sales_forecast_tbl[[#This Row],[Customer Name]],_xlfn.ANCHORARRAY(Assumptions!$C$34),Assumptions!$D$34:$D$107)} -> TRUE | E9: 3812 | F9: 4411 | G9: 939 | H9: 2763 | I9: 1598 | J9: 908 | K9: 919 | L9: 692 | M9: 939 | N9: 1142 | O9: 1893 | P9: 3051 | Q9: 4707.0845 | R9: =SUM(sales_forecast_tbl[[#This Row],[Feb-25]:[Jan-26]]) -> 23962.084 | S9: =sales_forecast_tbl[[#This Row],[Total]]/sales_forecast_tbl[[#Totals],[Total]] -> 0.0011715689 | Y9: 1.234807
B10: Cascade Distributors | C10: Corporate | D10: {=_xlfn.XLOOKUP(sales_forecast_tbl[[#This Row],[Customer Name]],_xlfn.ANCHORARRAY(Assumptions!$C$34),Assumptions!$D$34:$D$107)} -> TRUE | E10: 4697 | F10: 5095 | G10: 1097 | H10: 3270 | I10: 1945 | J10: 1093 | K10: 1100 | L10: 792 | M10: 1097 | N10: 1348 | O10: 2187 | P10: 3551 | Q10: 4747.2584 | R10: =SUM(sales_forecast_tbl[[#This Row],[Feb-25]:[Jan-26]]) -> 27322.258 | S10: =sales_forecast_tbl[[#This Row],[Total]]/sales_forecast_tbl[[#Totals],[Total]] -> 0.0013358566 | Y10: 1.0107001
B11: Evergreen Specialty Foods | C11: Corporate | D11: {=_xlfn.XLOOKUP(sales_forecast_tbl[[#This Row],[Customer Name]],_xlfn.ANCHORARRAY(Assumptions!$C$34),Assumptions!$D$34:$D$107)} -> TRUE | E11: 7837 | F11: 8915 | G11: 1873 | H11: 5446 | I11: 3267 | J11: 1856 | K11: 1834 | L11: 1391 | M11: 1867 | N11: 2331 | O11: 3700 | P11: 5924 | Q11: 9602.7628 | R11: =SUM(sales_forecast_tbl[[#This Row],[Feb-25]:[Jan-26]]) -> 48006.763 | S11: =sales_forecast_tbl[[#This Row],[Total]]/sales_forecast_tbl[[#Totals],[Total]] -> 0.002347176 | Y11: 1.2253111
B12: Pinnacle Chocolates LLC | C12: Corporate | D12: {=_xlfn.XLOOKUP(sales_forecast_tbl[[#This Row],[Customer Name]],_xlfn.ANCHORARRAY(Assumptions!$C$34),Assumptions!$D$34:$D$107)} -> TRUE | E12: 8340 | F12: 9468 | G12: 1924 | H12: 5736 | I12: 3425 | J12: 1930 | K12: 1913 | L12: 1439 | M12: 1924 | N12: 2457 | O12: 3975 | P12: 6480 | Q12: 8821.416 | R12: =SUM(sales_forecast_tbl[[#This Row],[Feb-25]:[Jan-26]]) -> 49492.416 | S12: =sales_forecast_tbl[[#This Row],[Total]]/sales_forecast_tbl[[#Totals],[Total]] -> 0.0024198135 | Y12: 1.0577237
B13: Granite Corporate Catering | C13: Corporate | D13: {=_xlfn.XLOOKUP(sales_forecast_tbl[[#This Row],[Customer Name]],_xlfn.ANCHORARRAY(Assumptions!$C$34),Assumptions!$D$34:$D$107)} -> TRUE | E13: 7638 | F13: 8281 | G13: 1742 | H13: 5257 | I13: 3018 | J13: 1750 | K13: 1781 | L13: 1354 | M13: 1753 | N13: 2175 | O13: 3499 | P13: 5871 | Q13: 7863.5304 | R13: =SUM(sales_forecast_tbl[[#This Row],[Feb-25]:[Jan-26]]) -> 44344.53 | S13: =sales_forecast_tbl[[#This Row],[Total]]/sales_forecast_tbl[[#Totals],[Total]] -> 0.0021681199 | Y13: 1.0295274
B14: Sequoia Imports | C14: Corporate | D14: {=_xlfn.XLOOKUP(sales_forecast_tbl[[#This Row],[Customer Name]],_xlfn.ANCHORARRAY(Assumptions!$C$34),Assumptions!$D$34:$D$107)} -> TRUE | E14: 8037 | F14: 9177 | G14: 1947 | H14: 5647 | I14: 3329 | J14: 1911 | K14: 1887 | L14: 1433 | M14: 1931 | N14: 2352 | O14: 3915 | P14: 6282 | Q14: 7495.0651 | R14: =SUM(sales_forecast_tbl[[#This Row],[Feb-25]:[Jan-26]]) -> 47306.065 | S14: =sales_forecast_tbl[[#This Row],[Total]]/sales_forecast_tbl[[#Totals],[Total]] -> 0.0023129171 | Y14: 0.93257001
B15: Blue Horizon Delicacies | C15: Corporate | D15: {=_xlfn.XLOOKUP(sales_forecast_tbl[[#This Row],[Customer Name]],_xlfn.ANCHORARRAY(Assumptions!$C$34),Assumptions!$D$34:$D$107)} -> TRUE | E15: 8179 | F15: 8997 | G15: 1894 | H15: 5730 | I15: 3286 | J15: 1881 | K15: 1933 | L15: 1394 | M15: 1908 | N15: 2413 | O15: 3727 | P15: 6203 | Q15: 8488.4618 | R15: =SUM(sales_forecast_tbl[[#This Row],[Feb-25]:[Jan-26]]) -> 47854.462 | S15: =sales_forecast_tbl[[#This Row],[Total]]/sales_forecast_tbl[[#Totals],[Total]] -> 0.0023397296 | Y15: 1.0378361
B16: Paramount Foodservice | C16: Corporate | D16: {=_xlfn.XLOOKUP(sales_forecast_tbl[[#This Row],[Customer Name]],_xlfn.ANCHORARRAY(Assumptions!$C$34),Assumptions!$D$34:$D$107)} -> TRUE | E16: 12457 | F16: 13709 | G16: 2920 | H16: 8871 | I16: 5045 | J16: 2942 | K16: 2934 | L16: 2187 | M16: 2919 | N16: 3676 | O16: 5788 | P16: 9331 | Q16: 12141.297 | R16: =SUM(sales_forecast_tbl[[#This Row],[Feb-25]:[Jan-26]]) -> 72463.297 | S16: =sales_forecast_tbl[[#This Row],[Total]]/sales_forecast_tbl[[#Totals],[Total]] -> 0.0035429199 | Y16: 0.97465661
B17: Crestline Premium Goods | C17: Corporate | D17: {=_xlfn.XLOOKUP(sales_forecast_tbl[[#This Row],[Customer Name]],_xlfn.ANCHORARRAY(Assumptions!$C$34),Assumptions!$D$34:$D$107)} -> TRUE | E17: 13889 | F17: 15300 | G17: 3209 | H17: 9434 | I17: 5675 | J17: 3266 | K17: 3209 | L17: 2371 | M17: 3202 | N17: 4050 | O17: 6486 | P17: 10209 | Q17: 16855.905 | R17: =SUM(sales_forecast_tbl[[#This Row],[Feb-25]:[Jan-26]]) -> 83266.905 | S17: =sales_forecast_tbl[[#This Row],[Total]]/sales_forecast_tbl[[#Totals],[Total]] -> 0.0040711365 | Y17: 1.2136154
... B79: MyBarringtonChocolate.com | C79: eCommerce | D79: {=_xlfn.XLOOKUP(sales_forecast_tbl[[#This Row],[Customer Name]],_xlfn.ANCHORARRAY(Assumptions!$C$34),Assumptions!$D$34:$D$107)} -> TRUE | E79: 600983 | F79: 723218.78 | G79: 135714.33 | H79: 455846.14 | I79: 251983.45 | J79: 131812.19 | K79: 150636.63 | L79: 103984.52 | M79: 144056.75 | N79: 178458.43 | O79: 300555.16 | P79: 487067.22 | Q79: 679471.93 | R79: =SUM(sales_forecast_tbl[[#This Row],[Feb-25]:[Jan-26]]) -> 3742805.5 | S79: =sales_forecast_tbl[[#This Row],[Total]]/sales_forecast_tbl[[#Totals],[Total]] -> 0.18299554 | Y79: 1.1306009
B80: Total | E80: =SUBTOTAL(109,sales_forecast_tbl[Jan-25]) -> 3455459.7 | F80: =SUBTOTAL(109,sales_forecast_tbl[Feb-25]) -> 4821599.4 | G80: =SUBTOTAL(109,sales_forecast_tbl[Mar-25]) -> 627500.59 | H80: =SUBTOTAL(109,sales_forecast_tbl[Apr-25]) -> 1853885 | I80: =SUBTOTAL(109,sales_forecast_tbl[May-25]) -> 1083761.5 | J80: =SUBTOTAL(109,sales_forecast_tbl[Jun-25]) -> 639222.19 | K80: =SUBTOTAL(109,sales_forecast_tbl[Jul-25]) -> 645364.74 | L80: =SUBTOTAL(109,sales_forecast_tbl[Aug-25]) -> 544310.92 | M80: =SUBTOTAL(109,sales_forecast_tbl[Sep-25]) -> 1097387.9 | N80: =SUBTOTAL(109,sales_forecast_tbl[Oct-25]) -> 1253965.3 | O80: =SUBTOTAL(109,sales_forecast_tbl[Nov-25]) -> 1694424.8 | P80: =SUBTOTAL(109,sales_forecast_tbl[Dec-25]) -> 2472035.5 | Q80: =SUBTOTAL(109,sales_forecast_tbl[Jan-26]) -> 3719529.8 | R80: =SUBTOTAL(109,sales_forecast_tbl[Total]) -> 20452988 | S80: =sales_forecast_tbl[[#Totals],[Total]]/sales_forecast_tbl[[#Totals],[Total]] -> 1
B81: % of Total | E81: =sales_forecast_tbl[[#Totals],[Jan-25]]/sales_forecast_tbl[[#Totals],[Total]] -> 0.16894645 | F81: =sales_forecast_tbl[[#Totals],[Feb-25]]/sales_forecast_tbl[[#Totals],[Total]] -> 0.23574059 | G81: =sales_forecast_tbl[[#Totals],[Mar-25]]/sales_forecast_tbl[[#Totals],[Total]] -> 0.030680143 | H81: =sales_forecast_tbl[[#Totals],[Apr-25]]/sales_forecast_tbl[[#Totals],[Total]] -> 0.090641283 | I81: =sales_forecast_tbl[[#Totals],[May-25]]/sales_forecast_tbl[[#Totals],[Total]] -> 0.052987929 | J81: =sales_forecast_tbl[[#Totals],[Jun-25]]/sales_forecast_tbl[[#Totals],[Total]] -> 0.031253243 | K81: =sales_forecast_tbl[[#Totals],[Jul-25]]/sales_forecast_tbl[[#Totals],[Total]] -> 0.031553568 | L81: =sales_forecast_tbl[[#Totals],[Aug-25]]/sales_forecast_tbl[[#Totals],[Total]] -> 0.026612783 | M81: =sales_forecast_tbl[[#Totals],[Sep-25]]/sales_forecast_tbl[[#Totals],[Total]] -> 0.05365416 | N81: =sales_forecast_tbl[[#Totals],[Oct-25]]/sales_forecast_tbl[[#Totals],[Total]] -> 0.061309641 | O81: =sales_forecast_tbl[[#Totals],[Nov-25]]/sales_forecast_tbl[[#Totals],[Total]] -> 0.082844855 | P81: =sales_forecast_tbl[[#Totals],[Dec-25]]/sales_forecast_tbl[[#Totals],[Total]] -> 0.12086427 | Q81: =sales_forecast_tbl[[#Totals],[Jan-26]]/sales_forecast_tbl[[#Totals],[Total]] -> 0.18185753 | R81: =sales_forecast_tbl[[#Totals],[Total]]/sales_forecast_tbl[[#Totals],[Total]] -> 1
B83: Category: | E83: 45682 | F83: Feb-25 | G83: Mar-25 | H83: Apr-25 | I83: May-25 | J83: Jun-25 | K83: Jul-25 | L83: Aug-25 | M83: Sep-25 | N83: Oct-25 | O83: Nov-25 | P83: Dec-25 | Q83: 45683 | R83: Total
B84: {=_xlfn.UNIQUE(sales_forecast_tbl[Category])} -> Corporate | E84: {=SUMIFS(sales_forecast_tbl[Jan-25],sales_forecast_tbl[Category],_xlfn.ANCHORARRAY($B$84))} -> 2264527 | F84: {=SUMIFS(sales_forecast_tbl[Feb-25],sales_forecast_tbl[Category],_xlfn.ANCHORARRAY($B$84))} -> 3434431 | G84: {=SUMIFS(sales_forecast_tbl[Mar-25],sales_forecast_tbl[Category],_xlfn.ANCHORARRAY($B$84))} -> 348971 | H84: {=SUMIFS(sales_forecast_tbl[Apr-25],sales_forecast_tbl[Category],_xlfn.ANCHORARRAY($B$84))} -> 982599 | I84: {=SUMIFS(sales_forecast_tbl[May-25],sales_forecast_tbl[Category],_xlfn.ANCHORARRAY($B$84))} -> 581130 | J84: {=SUMIFS(sales_forecast_tbl[Jun-25],sales_forecast_tbl[Category],_xlfn.ANCHORARRAY($B$84))} -> 365450 | K84: {=SUMIFS(sales_forecast_tbl[Jul-25],sales_forecast_tbl[Category],_xlfn.ANCHORARRAY($B$84))} -> 355310 | L84: {=SUMIFS(sales_forecast_tbl[Aug-25],sales_forecast_tbl[Category],_xlfn.ANCHORARRAY($B$84))} -> 335687 | M84: {=SUMIFS(sales_forecast_tbl[Sep-25],sales_forecast_tbl[Category],_xlfn.ANCHORARRAY($B$84))} -> 810929 | N84: {=SUMIFS(sales_forecast_tbl[Oct-25],sales_forecast_tbl[Category],_xlfn.ANCHORARRAY($B$84))} -> 896960 | O84: {=SUMIFS(sales_forecast_tbl[Nov-25],sales_forecast_tbl[Category],_xlfn.ANCHORARRAY($B$84))} -> 1111650 | P84: {=SUMIFS(sales_forecast_tbl[Dec-25],sales_forecast_tbl[Category],_xlfn.ANCHORARRAY($B$84))} -> 1515975 | Q84: {=SUMIFS(sales_forecast_tbl[Jan-26],sales_forecast_tbl[Category],_xlfn.ANCHORARRAY($B$84))} -> 2432827.5 | R84: {=SUMIFS(sales_forecast_tbl[Total],sales_forecast_tbl[Category],_xlfn.ANCHORARRAY($B$84))} -> 13171920 | S84: =R84/R$87 -> 0.64400956
B85: Retail | E85: 589949.66 | F85: 663949.61 | G85: 142815.26 | H85: 415439.91 | I85: 250648.02 | J85: 141960 | K85: 139418.11 | L85: 104639.4 | M85: 142402.12 | N85: 178546.9 | O85: 282219.64 | P85: 468993.31 | Q85: 607230.37 | R85: 3538262.7 | S85: =R85/R$87 -> 0.17299491
B86: eCommerce | E86: 600983 | F86: 723218.78 | G86: 135714.33 | H86: 455846.14 | I86: 251983.45 | J86: 131812.19 | K86: 150636.63 | L86: 103984.52 | M86: 144056.75 | N86: 178458.43 | O86: 300555.16 | P86: 487067.22 | Q86: 679471.93 | R86: 3742805.5 | S86: =R86/R$87 -> 0.18299554
B87: Total | E87: =SUM(_xlfn.ANCHORARRAY(E84)) -> 3455459.7 | F87: =SUM(_xlfn.ANCHORARRAY(F84)) -> 4821599.4 | G87: =SUM(_xlfn.ANCHORARRAY(G84)) -> 627500.59 | H87: =SUM(_xlfn.ANCHORARRAY(H84)) -> 1853885 | I87: =SUM(_xlfn.ANCHORARRAY(I84)) -> 1083761.5 | J87: =SUM(_xlfn.ANCHORARRAY(J84)) -> 639222.19 | K87: =SUM(_xlfn.ANCHORARRAY(K84)) -> 645364.74 | L87: =SUM(_xlfn.ANCHORARRAY(L84)) -> 544310.92 | ... R87: =SUM(_xlfn.ANCHORARRAY(R84)) -> 20452988 | S87: =R87/R$87 -> 1
B88: % of Total | E88: =E87/$R$87 -> 0.16894645 | F88: =F87/$R$87 -> 0.23574059 | G88: =G87/$R$87 -> 0.030680143 | H88: =H87/$R$87 -> 0.090641283 | I88: =I87/$R$87 -> 0.052987929 | J88: =J87/$R$87 -> 0.031253243 | K88: =K87/$R$87 -> 0.031553568 | L88: =L87/$R$87 -> 0.026612783 | ... R88: =R87/$R$87 -> 1

Sheet Payroll
B1: {=Company_Name} -> Pinnacle Supplier DBA Candy Confection
B2: Full-Time W2 Payroll Schedule
B3: All figures in USD
P4: Salary Forecast | AE4: Bonus Accrual Forecast
B5: Employee_ID | C5: Employee_Name | D5: Job_Title | E5: Job_Category | F5: Hired? | G5: Start_Date | H5: End_Date | I5: Salary | J5: Deductions | K5: Net_Salary | L5: Annual_Bonus | M5: Pro_Rata_Bonus | N5: Pay_Bonus? | O5: Bonus_Month | P5: 1/31/2025 | Q5: 2/28/2025 | R5: 3/31/2025 | S5: 4/30/2025 | T5: 5/31/2025 | U5: 6/30/2025 | V5: 7/31/2025 | W5: 8/31/2025 | X5: 9/30/2025 | Y5: 10/31/2025 | Z5: 11/30/2025 | AA5: 12/31/2025 | AB5: 1/31/2026 | AC5: Salary_Total | AE5: 1/31/2025 | AF5: 2/28/2025 | AG5: 3/31/2025 | AH5: 4/30/2025 | AI5: 5/31/2025 | AJ5: 6/30/2025 | AK5: 7/31/2025 | AL5: 8/31/2025 | AM5: 9/30/2025 | AN5: 10/31/2025 | AO5: 11/30/2025 | AP5: 12/31/2025 | AQ5: 1/31/2026 | AR5: Bonus_Total
